<?xml version="1.0"?>
<robot xmlns:xacro="http://ros.org/wiki/xacro">
  <xacro:macro name="ezgripper_dual" params="prefix parent_link">

    <link name="${prefix}_ezgripper_palm_link">
      <visual>
        <origin xyz="0 0 0" rpy="0 0 0"/>
        <geometry>
          <mesh filename="package://ezgripper_driver/meshes/ezgripper_gen2/SAKE_Palm_Dual_Gen2.stl"/>
        </geometry>
      </visual>
      <collision>
        <origin xyz="0 0 0" rpy="0 0 0"/>
        <geometry>
          <mesh filename="package://ezgripper_driver/meshes/ezgripper_gen2/SAKE_Palm_Dual_Gen2.stl"/>
        </geometry>
      </collision>
      <inertial>
        <mass value=".3"/>
        <inertia ixx="0.01" ixy="0.0" ixz="0.0" iyy="0.01" iyz="0.0" izz="0.01"/>
      </inertial>
    </link>

    <joint name="${prefix}_ezgripper_connect" type="fixed">
      <!-- <xacro:insert_block name="origin" /> -->
      <!-- <origin rpy="0 0 0" xyz="0.049 0.0 0.2"/> -->
      <origin rpy="0 0 0" xyz="0.0 0.0 0.0"/>
      <parent link="${parent_link}"/>
      <child link="${prefix}_ezgripper_palm_link"/>
      <axis xyz="0 0 0"/>
      <limit effort="0" lower="-1.57075" upper="0.25" velocity="3.67"/>
    </joint>

    <xacro:ezgripper_finger_L1 prefix="${prefix}" postfix="1" reflect="1" />
    <xacro:ezgripper_finger_L1 prefix="${prefix}" postfix="2" reflect="1" />

    <xacro:ezgripper_finger_L2 prefix="${prefix}" postfix="1" reflect="1" />
    <xacro:ezgripper_finger_L2 prefix="${prefix}" postfix="2" reflect="1" />

    <xacro:ezgripper_knuckle_palm_L1 prefix="${prefix}" postfix="1" reflectY="1" reflectZ="1" reflectR="1" mimic_test="false"/>
    <xacro:ezgripper_knuckle_palm_L1 prefix="${prefix}" postfix="2" reflectY="-1" reflectZ="1" reflectR="-1" mimic_test="true"/>

    <xacro:ezgripper_knuckle_L1_L2 prefix="${prefix}" postfix="1" reflectY="1" reflectZ="1" reflectR="-1" mimic_test="false"/>
    <xacro:ezgripper_knuckle_L1_L2 prefix="${prefix}" postfix="2" reflectY="-1" reflectZ="1" reflectR="1" mimic_test="true"/>

  </xacro:macro>

  <!-- links -->

  <xacro:macro name="ezgripper_finger_L1" params="prefix postfix reflect">
    <link name="${prefix}_ezgripper_finger_L1_${postfix}">
      <visual>
        <origin xyz="0 0 0" rpy="0 0 0"/>
        <geometry>
          <mesh filename="package://ezgripper_driver/meshes/ezgripper_gen2/SAKE_Finger_L1_Gen2.stl"/>
        </geometry>
      </visual>
      <collision>
        <origin xyz="0 0 0" rpy="0 0 0"/>
        <geometry>
          <mesh filename="package://ezgripper_driver/meshes/ezgripper_gen2/SAKE_Finger_L1_Gen2.stl"/>
        </geometry>
      </collision>
      <inertial>
        <mass value=".025"/>
        <inertia ixx="0.01" ixy="0.0" ixz="0.0" iyy="0.01" iyz="0.0" izz="0.01"/>
      </inertial>
    </link>
  </xacro:macro>

  <xacro:macro name="ezgripper_finger_L2" params="prefix postfix reflect">
    <link name="${prefix}_ezgripper_finger_L2_${postfix}">
      <visual>
        <origin xyz="0 0 0" rpy="0 0 0"/>
        <geometry>
          <mesh filename="package://ezgripper_driver/meshes/ezgripper_gen2/SAKE_Finger_L2_Gen2.stl"/>
        </geometry>
      </visual>
      <collision>
        <origin xyz="0 0 0" rpy="0 0 0"/>
        <geometry>
          <mesh filename="package://ezgripper_driver/meshes/ezgripper_gen2/SAKE_Finger_L2_Gen2.stl"/>
        </geometry>
      </collision>
      <inertial>
        <mass value=".025"/>
        <inertia ixx="0.01" ixy="0.0" ixz="0.0" iyy="0.01" iyz="0.0" izz="0.01"/>
      </inertial>
    </link>
  </xacro:macro>

  <!-- joints -->

  <xacro:macro name="ezgripper_knuckle_palm_L1" params="prefix postfix reflectY reflectZ reflectR mimic_test">
    <joint name="${prefix}_ezgripper_knuckle_palm_L1_${postfix}" type="revolute">
      <parent link="${prefix}_ezgripper_palm_link"/>
      <child link="${prefix}_ezgripper_finger_L1_${postfix}"/>
      <origin xyz="0.072569 ${reflectY*0.03} 0" rpy="${-1.5708 * reflectR} 0 ${1.57075 * reflectR}"/>
      <axis xyz="0 1 0"/>
      <limit lower="0" upper="1.94" effort="1" velocity="3.67"/>
      <xacro:if value="${mimic_test}">
           <mimic joint="${prefix}_ezgripper_knuckle_palm_L1_1"/>
      </xacro:if>
    </joint>
  </xacro:macro>

  <xacro:macro name="ezgripper_knuckle_L1_L2" params="prefix postfix reflectY reflectZ reflectR mimic_test">
    <joint name="${prefix}_ezgripper_knuckle_L1_L2_${postfix}" type="revolute">
      <parent link="${prefix}_ezgripper_finger_L1_${postfix}"/>
      <child link="${prefix}_ezgripper_finger_L2_${postfix}"/>
      <origin xyz="0.052 0 0" rpy="0 0 0"/>
      <!-- origin xyz="0.06 0 0" rpy="${3.14159 * reflectR} 0 0"/-->
      <axis xyz="0 1 0"/>
      <limit lower="0" upper="1.94" effort="1" velocity="3.67"/>
      <xacro:if value="${mimic_test}">
           <mimic joint="${prefix}_ezgripper_knuckle_L1_L2_1"/>
      </xacro:if>
    </joint>
  </xacro:macro>

</robot>


